{"name": "Login with invalid credentials", "status": "broken", "statusDetails": {"message": "urllib3.exceptions.MaxRetryError: HTTPConnectionPool(host='localhost', port=62630): Max retries exceeded with url: /session/4418d4bbf97f5e13b7ce6a1405ca7fec/element (Caused by NewConnectionError('<urllib3.connection.HTTPConnection object at 0x000002B76FDC9590>: Failed to establish a new connection: [WinError 10061] No connection could be made because the target machine actively refused it'))\n", "trace": "  File \"C:\\Users\\Joao Sousa\\AppData\\Roaming\\Python\\Python311\\site-packages\\behave\\model.py\", line 1329, in run\n    match.run(runner.context)\n  File \"C:\\Users\\Joao Sousa\\AppData\\Roaming\\Python\\Python311\\site-packages\\behave\\matchers.py\", line 98, in run\n    self.func(context, *args, **kwargs)\n  File \"features\\steps\\login.py\", line 43, in is_invalid_login\n    LoginPage.is_invalid_user(login)\n  File \"C:\\Users\\Joao Sousa\\PycharmProjects\\behave\\features\\pages\\LoginPage.py\", line 135, in is_invalid_user\n    invalid_login = self.get_invalid_login()\n                    ^^^^^^^^^^^^^^^^^^^^^^^^\n  File \"C:\\Users\\Joao Sousa\\PycharmProjects\\behave\\features\\pages\\LoginPage.py\", line 105, in get_invalid_login\n    return self.find_element(*Locator.invalid_login)\n           ^^^^^^^^^^^^^^^^^^^^^^^^^^^^^^^^^^^^^^^^^\n  File \"C:\\Users\\Joao Sousa\\PycharmProjects\\behave\\features\\pages\\BasePage.py\", line 21, in find_element\n    return self.driver.find_element(*locator)\n           ^^^^^^^^^^^^^^^^^^^^^^^^^^^^^^^^^^\n  File \"C:\\Users\\Joao Sousa\\AppData\\Roaming\\Python\\Python311\\site-packages\\selenium\\webdriver\\remote\\webdriver.py\", line 861, in find_element\n    return self.execute(Command.FIND_ELEMENT, {\"using\": by, \"value\": value})[\"value\"]\n           ^^^^^^^^^^^^^^^^^^^^^^^^^^^^^^^^^^^^^^^^^^^^^^^^^^^^^^^^^^^^^^^^^\n  File \"C:\\Users\\Joao Sousa\\AppData\\Roaming\\Python\\Python311\\site-packages\\selenium\\webdriver\\remote\\webdriver.py\", line 442, in execute\n    response = self.command_executor.execute(driver_command, params)\n               ^^^^^^^^^^^^^^^^^^^^^^^^^^^^^^^^^^^^^^^^^^^^^^^^^^^^^\n  File \"C:\\Users\\Joao Sousa\\AppData\\Roaming\\Python\\Python311\\site-packages\\selenium\\webdriver\\remote\\remote_connection.py\", line 294, in execute\n    return self._request(command_info[0], url, body=data)\n           ^^^^^^^^^^^^^^^^^^^^^^^^^^^^^^^^^^^^^^^^^^^^^^\n  File \"C:\\Users\\Joao Sousa\\AppData\\Roaming\\Python\\Python311\\site-packages\\selenium\\webdriver\\remote\\remote_connection.py\", line 316, in _request\n    response = self._conn.request(method, url, body=body, headers=headers)\n               ^^^^^^^^^^^^^^^^^^^^^^^^^^^^^^^^^^^^^^^^^^^^^^^^^^^^^^^^^^^\n  File \"C:\\Users\\Joao Sousa\\AppData\\Roaming\\Python\\Python311\\site-packages\\urllib3\\request.py\", line 78, in request\n    return self.request_encode_body(\n           ^^^^^^^^^^^^^^^^^^^^^^^^^\n  File \"C:\\Users\\Joao Sousa\\AppData\\Roaming\\Python\\Python311\\site-packages\\urllib3\\request.py\", line 170, in request_encode_body\n    return self.urlopen(method, url, **extra_kw)\n           ^^^^^^^^^^^^^^^^^^^^^^^^^^^^^^^^^^^^^\n  File \"C:\\Users\\Joao Sousa\\AppData\\Roaming\\Python\\Python311\\site-packages\\urllib3\\poolmanager.py\", line 376, in urlopen\n    response = conn.urlopen(method, u.request_uri, **kw)\n               ^^^^^^^^^^^^^^^^^^^^^^^^^^^^^^^^^^^^^^^^^\n  File \"C:\\Users\\Joao Sousa\\AppData\\Roaming\\Python\\Python311\\site-packages\\urllib3\\connectionpool.py\", line 815, in urlopen\n    return self.urlopen(\n           ^^^^^^^^^^^^^\n  File \"C:\\Users\\Joao Sousa\\AppData\\Roaming\\Python\\Python311\\site-packages\\urllib3\\connectionpool.py\", line 815, in urlopen\n    return self.urlopen(\n           ^^^^^^^^^^^^^\n  File \"C:\\Users\\Joao Sousa\\AppData\\Roaming\\Python\\Python311\\site-packages\\urllib3\\connectionpool.py\", line 815, in urlopen\n    return self.urlopen(\n           ^^^^^^^^^^^^^\n  File \"C:\\Users\\Joao Sousa\\AppData\\Roaming\\Python\\Python311\\site-packages\\urllib3\\connectionpool.py\", line 787, in urlopen\n    retries = retries.increment(\n              ^^^^^^^^^^^^^^^^^^\n  File \"C:\\Users\\Joao Sousa\\AppData\\Roaming\\Python\\Python311\\site-packages\\urllib3\\util\\retry.py\", line 592, in increment\n    raise MaxRetryError(_pool, url, error or ResponseError(cause))\n"}, "steps": [{"name": "Given Launch the browser", "status": "passed", "start": 1691072390014, "stop": 1691072390988}, {"name": "When Open the https://courses.ultimateqa.com/users/sign_in website", "status": "passed", "start": 1691072390988, "stop": 1691072393068}, {"name": "Then The login portal has been opened", "status": "passed", "start": 1691072393068, "stop": 1691072393074}, {"name": "When Provide the email \"invalidemail@gmail.com\" and password \"testeserror\"", "status": "passed", "start": 1691072393074, "stop": 1691072393277}, {"name": "Then Click on the Sign in button", "status": "passed", "start": 1691072393277, "stop": 1691072393335}, {"name": "Then Login is failed and invalid message is displayed", "status": "broken", "statusDetails": {"message": "urllib3.exceptions.MaxRetryError: HTTPConnectionPool(host='localhost', port=62630): Max retries exceeded with url: /session/4418d4bbf97f5e13b7ce6a1405ca7fec/element (Caused by NewConnectionError('<urllib3.connection.HTTPConnection object at 0x000002B76FDC9590>: Failed to establish a new connection: [WinError 10061] No connection could be made because the target machine actively refused it'))\n", "trace": "  File \"C:\\Users\\Joao Sousa\\AppData\\Roaming\\Python\\Python311\\site-packages\\behave\\model.py\", line 1329, in run\n    match.run(runner.context)\n  File \"C:\\Users\\Joao Sousa\\AppData\\Roaming\\Python\\Python311\\site-packages\\behave\\matchers.py\", line 98, in run\n    self.func(context, *args, **kwargs)\n  File \"features\\steps\\login.py\", line 43, in is_invalid_login\n    LoginPage.is_invalid_user(login)\n  File \"C:\\Users\\Joao Sousa\\PycharmProjects\\behave\\features\\pages\\LoginPage.py\", line 135, in is_invalid_user\n    invalid_login = self.get_invalid_login()\n                    ^^^^^^^^^^^^^^^^^^^^^^^^\n  File \"C:\\Users\\Joao Sousa\\PycharmProjects\\behave\\features\\pages\\LoginPage.py\", line 105, in get_invalid_login\n    return self.find_element(*Locator.invalid_login)\n           ^^^^^^^^^^^^^^^^^^^^^^^^^^^^^^^^^^^^^^^^^\n  File \"C:\\Users\\Joao Sousa\\PycharmProjects\\behave\\features\\pages\\BasePage.py\", line 21, in find_element\n    return self.driver.find_element(*locator)\n           ^^^^^^^^^^^^^^^^^^^^^^^^^^^^^^^^^^\n  File \"C:\\Users\\Joao Sousa\\AppData\\Roaming\\Python\\Python311\\site-packages\\selenium\\webdriver\\remote\\webdriver.py\", line 861, in find_element\n    return self.execute(Command.FIND_ELEMENT, {\"using\": by, \"value\": value})[\"value\"]\n           ^^^^^^^^^^^^^^^^^^^^^^^^^^^^^^^^^^^^^^^^^^^^^^^^^^^^^^^^^^^^^^^^^\n  File \"C:\\Users\\Joao Sousa\\AppData\\Roaming\\Python\\Python311\\site-packages\\selenium\\webdriver\\remote\\webdriver.py\", line 442, in execute\n    response = self.command_executor.execute(driver_command, params)\n               ^^^^^^^^^^^^^^^^^^^^^^^^^^^^^^^^^^^^^^^^^^^^^^^^^^^^^\n  File \"C:\\Users\\Joao Sousa\\AppData\\Roaming\\Python\\Python311\\site-packages\\selenium\\webdriver\\remote\\remote_connection.py\", line 294, in execute\n    return self._request(command_info[0], url, body=data)\n           ^^^^^^^^^^^^^^^^^^^^^^^^^^^^^^^^^^^^^^^^^^^^^^\n  File \"C:\\Users\\Joao Sousa\\AppData\\Roaming\\Python\\Python311\\site-packages\\selenium\\webdriver\\remote\\remote_connection.py\", line 316, in _request\n    response = self._conn.request(method, url, body=body, headers=headers)\n               ^^^^^^^^^^^^^^^^^^^^^^^^^^^^^^^^^^^^^^^^^^^^^^^^^^^^^^^^^^^\n  File \"C:\\Users\\Joao Sousa\\AppData\\Roaming\\Python\\Python311\\site-packages\\urllib3\\request.py\", line 78, in request\n    return self.request_encode_body(\n           ^^^^^^^^^^^^^^^^^^^^^^^^^\n  File \"C:\\Users\\Joao Sousa\\AppData\\Roaming\\Python\\Python311\\site-packages\\urllib3\\request.py\", line 170, in request_encode_body\n    return self.urlopen(method, url, **extra_kw)\n           ^^^^^^^^^^^^^^^^^^^^^^^^^^^^^^^^^^^^^\n  File \"C:\\Users\\Joao Sousa\\AppData\\Roaming\\Python\\Python311\\site-packages\\urllib3\\poolmanager.py\", line 376, in urlopen\n    response = conn.urlopen(method, u.request_uri, **kw)\n               ^^^^^^^^^^^^^^^^^^^^^^^^^^^^^^^^^^^^^^^^^\n  File \"C:\\Users\\Joao Sousa\\AppData\\Roaming\\Python\\Python311\\site-packages\\urllib3\\connectionpool.py\", line 815, in urlopen\n    return self.urlopen(\n           ^^^^^^^^^^^^^\n  File \"C:\\Users\\Joao Sousa\\AppData\\Roaming\\Python\\Python311\\site-packages\\urllib3\\connectionpool.py\", line 815, in urlopen\n    return self.urlopen(\n           ^^^^^^^^^^^^^\n  File \"C:\\Users\\Joao Sousa\\AppData\\Roaming\\Python\\Python311\\site-packages\\urllib3\\connectionpool.py\", line 815, in urlopen\n    return self.urlopen(\n           ^^^^^^^^^^^^^\n  File \"C:\\Users\\Joao Sousa\\AppData\\Roaming\\Python\\Python311\\site-packages\\urllib3\\connectionpool.py\", line 787, in urlopen\n    retries = retries.increment(\n              ^^^^^^^^^^^^^^^^^^\n  File \"C:\\Users\\Joao Sousa\\AppData\\Roaming\\Python\\Python311\\site-packages\\urllib3\\util\\retry.py\", line 592, in increment\n    raise MaxRetryError(_pool, url, error or ResponseError(cause))\n"}, "start": 1691072393335, "stop": 1691072421855}, {"name": "Then Close the browser", "status": "skipped", "start": 1691072421856, "stop": 1691072421856}], "start": 1691072390013, "stop": 1691072421856, "uuid": "a1ebf4db-daf7-466e-960b-fac4d0053d0a", "historyId": "a4f04cbbbb704ce2d8ffb412af459adf", "fullName": "Validate the login feature: Login with invalid credentials", "labels": [{"name": "severity", "value": "normal"}, {"name": "feature", "value": "Validate the login feature"}, {"name": "framework", "value": "behave"}, {"name": "language", "value": "cpython3"}]}